<?xml version="1.0"?>
<robot xmlns:xacro="http://ros.org/wiki/xacro">

  <xacro:include filename="$(find bot_sim_stable)/urdf/roller/roller.transmission.xacro"/>
  <xacro:include filename="$(find bot_sim_stable)/urdf/roller/roller.gazebo.xacro"/>
  
  <xacro:macro name="roller_v0" params="prefix parent *joint_origin *joint_axis">
	<joint name="${prefix}_roller_joint" type="continuous">
	  <xacro:insert_block name="joint_origin"/>
	  <parent link="${parent}"/>
	  <child link="${prefix}_roller_link"/>
    <dynamics damping="0" friction="0.1"/>
	  <xacro:insert_block name="joint_axis"/>
	</joint>

	<link name="${prefix}_roller_link">
	  <visual>
		<geometry>
		  <mesh filename="package://bot_sim_stable/meshes/DAE/roller/roller.dae" scale="3 3 3"/>
		</geometry>
	  </visual>
	  <collision>
		<geometry>
		  <mesh filename="package://bot_sim_stable/meshes/STL/roller/roller.stl" scale="3 3 3"/>
		</geometry>
	  </collision>
	  <inertial>
		<origin xyz="0.0 0.0 0.0"/>
		<mass value="0.243"/>
		<inertia ixx="0.000305451" ixy="0" ixz="0" iyy="0.000083106" iyz="0" izz="0.000305451"/>
	  </inertial>
          <surface>
            <friction>
              <ode>
                <mu1>1.2</mu1>
                <mu2>1.2</mu2>
                <kp>1e15</kp>
                <kd>1e13</kd>
              </ode>
            </friction>
            <bounce>
              <restitution_coefficient>0.01</restitution_coefficient>
              <threshold>0</threshold>
            </bounce>
            <contact>
              <ode>
                <max_vel>10</max_vel>
              </ode>
            </contact>
          </surface>
	</link>
  </xacro:macro>
  
</robot>
